using System;

namespace Prj1Day1Con
{
    

   class Program
    {
                  
        static void Main()
        {
            int age;
            Console.WriteLine("Enter Age:");
            age = Convert.ToInt32(Console.ReadLine());
            try
            {
                if (age < 0)
                    throw new ArithmeticException("Invalid age - being negative");
            }
            catch(Exception ex)
            {
                Console.WriteLine(ex.Message);
            }

        }

    }
}











using System;

namespace Prj1Day1Con
{
    

   class Program
    {
                  
        static void Main()
        {
            int[] x = new int[5];  //x[0] to x[4]
            int d=2;
            try
            {
                try
                {
                    Console.WriteLine("Enter index of arr(0-4):");
                    int i = Convert.ToInt32(Console.ReadLine());
                    Console.WriteLine("Enter a number: numerator : ");
                    x[i] = Convert.ToInt32(Console.ReadLine());
                    Console.WriteLine("Enter another number: denominator : ");
                    d = Convert.ToInt32(Console.ReadLine());
                    Console.WriteLine("The square of the number enetered is : " + (d * d));
                    int y = x[i] / d;
                    Console.WriteLine("Div Result: " + y);

                }
                catch (FormatException e)
                {
                    Console.WriteLine("This is a " + e.Message + " exception!");
                    int p = d / 0;

                }
                catch (DivideByZeroException e)
                {
                    Console.WriteLine("This is a " + e.Message + " exception!");
                }
                //catch (Exception e)
                //{
                //    Console.WriteLine("This is a " + e.Message + " exception!");
                //}
            }
            catch (Exception e)
            {
                Console.WriteLine("Outer Catch: This is a " + e.Message + " exception!");
            }

        }

    }
}










using System;

namespace Prj1Day1Con
{
    

   class Program
    {
                  
        static void Main()
        {
            int[] x = new int[5];  //x[0] to x[4]
            int d=2;
            try
            {
                try
                {
                    Console.WriteLine("Enter a number: numerator : ");
                    x[5] = Convert.ToInt32(Console.ReadLine());
                    Console.WriteLine("Enter another number: denominator : ");
                    d = Convert.ToInt32(Console.ReadLine());
                    Console.WriteLine("The square of the number enetered is : " + (d * d));
                    int y = x[5] / d;
                    Console.WriteLine("Div Result: " + y);

                }
                catch (FormatException e)
                {
                    Console.WriteLine("This is a " + e.Message + " exception!");
                    int p = d / 0;

                }
                catch (DivideByZeroException e)
                {
                    Console.WriteLine("This is a " + e.Message + " exception!");
                }
                catch (Exception e)
                {
                    Console.WriteLine("This is a " + e.Message + " exception!");
                }
            }
            catch (Exception e)
            {
                Console.WriteLine("Outer Catch: This is a " + e.Message + " exception!");
            }

        }

    }
}












using System;

namespace Prj1Day1Con
{
    class Resource
    {
        public  void work()
        {
            Console.WriteLine("Some task done by the resource");
        }
        public  void closure()
        {
            Console.WriteLine("Resource Shut down...");
        }

    }


   class Program
    {
        static int div(int a, int b, Resource r)
        {
            r.work();
            try
            {
                Console.WriteLine("try: Division of : {0} / {1} : ", a, b);
                return a / b;
            }
            catch (DivideByZeroException e)
            {
                Console.WriteLine("catch: Divison by zero not possible, so res is 0");
                return 0;
            }
            finally
            {
                Console.WriteLine("finally: the resource will be closed");
                r.closure();
            }
        }
        static void Main()
        {
            Resource r=new Resource();
            int res = div(10, 2, r);
            Console.WriteLine(res);
            res = div(10, 0, r);
            Console.WriteLine(res);


        }

    }
}










using System;

namespace Prj1Day1Con
{
    class Resource
    {
        public static void work()
        {
            Console.WriteLine("Some task done by the resource");
        }
        public static void closure()
        {
            Console.WriteLine("Resource Shut down...");
        }

    }
   class Program
    {
        static void Main()
        {
            int x = 10;
            int d = 2;

            try
            {
                Resource.work();
                Console.WriteLine("Enter a number: numerator : ");
                x = Convert.ToInt32(Console.ReadLine());
                Console.WriteLine("Enter another number: denominator : ");
                d = Convert.ToInt32(Console.ReadLine());
                Console.WriteLine("The square of the number enetered is : " + (x * x));
                int y = x / d;
                Console.WriteLine("Div Result: " + y);
                
            }
            catch(FormatException e)
            {
                Console.WriteLine("This is a " + e.Message + " exception!");
               
            }
            catch(DivideByZeroException e)
            {
                Console.WriteLine("This is a " + e.Message + " exception!");
            }
            finally
            {
                Resource.closure();
            }
            Console.WriteLine("The Program continues..");

        }

    }
}












using System;

namespace Prj1Day1Con
{
   class Program
    {
        static void Main()
        {
            int x = 10;
            int d = 2;

            try
            {
                Console.WriteLine("Enter a number: numerator : ");
                x = Convert.ToInt32(Console.ReadLine());
                Console.WriteLine("Enter another number: denominator : ");
                d = Convert.ToInt32(Console.ReadLine());
                Console.WriteLine("The square of the number enetered is : " + (x * x));
                int y = x / d;
                Console.WriteLine("Div Result: " + y);
            }
            catch(FormatException e)
            {
                Console.WriteLine("This is a " + e.Message + " exception!");
            }
            catch(DivideByZeroException e)
            {
                Console.WriteLine("This is a " + e.Message + " exception!");
            }
            Console.WriteLine("The Program continues..");

        }

    }
}












using System;

namespace Prj1Day1Con
{
   class Program
    {
        static void Main()
        {
            Console.WriteLine("Enter a number: numerator : ");
            int x = Convert.ToInt32 (Console.ReadLine());
            Console.WriteLine("Enter another number: denominator : ");
            int d = Convert.ToInt32(Console.ReadLine());
            Console.WriteLine("The square of the number enetered is : " + (x*x));
            try
            {
                int y = x / d;
                Console.WriteLine("Div Result: " + y);
            }
            catch(DivideByZeroException e)
            {
                Console.WriteLine("This is a " + e.Message + " exception!");
            }
            Console.WriteLine("The Program continues..");

        }

    }
}


